Workbook

Sheet ppal B
E1: t/c usd/eur | F1: =Hoja1!H8 -> 1.1716 | G1: t/c usd/zar | H1: =Hoja1!H15 -> 16.4854 | I1: t/c usd/brl | J1: =Hoja1!H7 -> 5.0295 | K1: EEM | L1: =+S22 -> 0 | N1: Rent Spy | O1: =+I11 -> 0
B2: INFORME FINANCIERO 2026-FONDO JEB | D2: =TODAY() -> 46125 | E2: t/c usd/clp | F2: =+Hoja1!H6 -> 898.375 | G2: AAPL | H2: =Hoja1!H13 -> 257.4 | I2: USO | J2: =+S14 -> 0 | K2: ILF | L2: =+S23 -> 0
G3: SPY | H3: =Hoja1!H12 -> 679.25 | I3: GLD | J3: =+S11 -> 0 | K3: EWW
C4: Resultados Realizados | D4: Comisión | E4: MTM USD | G4: Risk | I4: MX | J4: =+S12 -> 0
I5: GOOG | J5: =+S29 -> 0 | K5: $$USDJPY | L5: =Hoja1!H16 -> 159.565
B6: P&L Opciones ETF-CDF-NDF-CLP | C6: =+opete!I107 -> 117.32766 | I6: FXI | J6: =+S20 -> 0 | K6: $$MEXUSD | L6: =Hoja1!H14 -> 17.34315
B7: P&L ETF | C7: =+etf!K102 -> 0
B8: P&L t10y | C8: =+t10y!J87 -> -1875 | I8: =+C39 -> 11000.715 | K8: $$USDCLP | L8: =Hoja1!H6 -> 898.375 | N8: -360000
B9: P&L Comm | K9: $$audUSD | L9: =Hoja1!H10 -> 0.7067 | N9: 252000
B10: P&L NDF | C10: =NDF!I30 -> 28223.04 | I10: Rt | K10: $$EURUSD | L10: =Hoja1!H8 -> 1.1716 | N10: =+N9+N8 -> -108000
B11: CLP-UF | C11: =UF!I45 -> 0 | I11: 0 | K11: $$ZARUSD | L11: =Hoja1!H15 -> 16.4854
B12: Div-2026 | K12: $$MXNUSD | L12: =Hoja1!H14 -> 17.34315
I13: Vol | K13: Xau | L13: =Hoja1!$H$11 -> 4720.375
E14: MTM USD | F14: POS USD | G14: MTM Cierre | I14: 0.3 | K14: $$BRLUSD | L14: =Hoja1!H7 -> 5.0295
B15: MTM Comm
B16: MTM NDF clp | E16: =+NDF!I99 -> -44.652695 | F16: =+NDF!F99 -> 2000
B17: MTM NDF fx | E17: =+NDF!I151 -> -15420 | F17: =NDF!K151 -> 0 | I17: Hedge MXN | K17: =+NDF!F120+opete!#REF!+opete!#REF! -> #REF!
B18: MTM t10y | E18: =t10y!J48 -> 0 | F18: 0 | G18: =7%*0.05*F18*-1*3 -> 0 | I18: Hedge BRL | K18: =+NDF!F112+opete!#REF!+opete!#REF! -> #REF!
B19: MTM ETF | E19: =etf!K44 -> 0 | F19: =etf!M44 -> 0 | I19: Hedge EUR | K19: =+NDF!F142+opete!#REF!+opete!#REF! -> #REF!
B20: Primas Op clp/usd | I20: Hedge ZAR | K20: =+NDF!F127+opete!#REF!+opete!#REF! -> #REF!
B21: MTM CLP-UF | E21: =UF!I26 -> 0 | F21: =+opete!#REF!+opete!#REF! -> #REF! | I21: Hedge aud/USD | K21: =+NDF!F151+opete!#REF!+opete!#REF! -> #REF!
B22: MTM Op ETF-CDF-NDF-CLP | E22: =+opete!I371 -> 0 | G22: =+opete!#REF! -> #REF! | I22: Hedge aud/JPY
B23: Pos.Neta USD clp | F23: =+F21+F16+F17 -> #REF! | I23: Hedge AUDEUR
B24: Pos.Neta USD TOTAL | D24: Pos USD Tot | E24: =SUM(E15:E23) -> -15464.653 | G24: =+opete!#REF! -> #REF! | I24: Hedge SPY | K24: =+etf!M29+etf!M38+etf!M40 -> 0
B25: Total USD (neto com) | C25: =SUM(C5:C14)+D25 -> 26465.367 | D25: =SUM(D6:D10) -> 0 | I25: Hedge FXI | K25: =+etf!#REF!+opete!#REF! -> #REF!
I26: Hedge MDB
I27: Hedge GOOG | K27: =+etf!#REF!+opete!#REF! -> #REF!
B28: Total USD | C28: =+C25 -> 26465.367 | I28: Hedge GLD | K28: =opete!#REF!+NDF!K160+etf!M14+etf!M15+etf!M16+etf!M17+etf!M18 -> #REF!
I29: Hedge USO | K29: =+etf!#REF!+opete!#REF! -> #REF!
I30: Hedge CRSP
I31: Hedge ETF | K31: =+etf!M44-opete!#REF! -> #REF!
E32: MTM total | F32: Plazo Prom | G32: =+G22-E22 -> #REF!
B33: Total P&L Hedge Fund | C33: =SUM(C28:C32) -> 26465.367 | E33: =SUM(E15:E23) -> -15464.653 | F33: =+opete!N371 -> 211.19802
E35: Stress
B36: Gastos Adm USD | C36: 0
B39: USD TOTAL | C39: =SUM(C33:C37)+E33 -> 11000.715 | D39: Retorno Mes | E39: =+C39/7000000 -> 0.0015715307
B45: FONDO JEB -2026
B48: Año | C48: Utilidad USD | D48: Fondos Util
C49: =+C39 -> 11000.715
B53: Total Resultado USD | C53: =SUM(C49:C52) -> 11000.715 | D53: =+opete!#REF! -> #REF!
...

Sheet NDF
F1: MONEDAS
A5: REALIZADAS
A8: Fecha Aper | B8: Contraparte | C8: Fecha cierre | D8: ticker | E8: País | F8: Monto | G8: Precio Inicial | H8: Precio Cierre | I8: MTM | J8: Rent | K8: Garantía | L8: Plazo | M8: Fix | N8: Settelment
A9: 46003 | B9: HSBC | D9: USDCLP | E9: CHILE | F9: -500 | G9: 909.01 | H9: 888.99 | I9: 11259.969 | J9: -0.02202396 | K9: 500000 | L9: -7 | M9: 46027 | N9: 46028
A10: 46003 | B10: HSBC | D10: USDCLP | E10: CHILE | F10: -500 | G10: 909.08 | H10: 888.99 | I10: 11299.34 | J10: -0.022099265 | K10: 500000 | L10: -7 | M10: 46027 | N10: 46028
A11: 46006 | B11: HSBC | D11: USDCLP | E11: CHILE | F11: -500 | G11: 911.79 | H11: 888.99 | I11: 12823.541 | J11: -0.025005758 | K11: 500000 | L11: -7 | M11: 46027 | N11: 46028
A12: 46006 | B12: HSBC | D12: USDCLP | E12: CHILE | F12: -500 | G12: 905.86 | H12: 888.99 | I12: 9488.2957 | J12: -0.018623187 | K12: 500000 | L12: -7 | M12: 46027 | N12: 46028
A13: 46009 | B13: HSBC | D13: USDCLP | E13: CHILE | F13: -500 | G13: 912.81 | H13: 888.99 | I13: 13397.226 | J13: -0.026095244 | K13: 500000 | L13: -7 | M13: 46027 | N13: 46028
A14: 46009 | B14: HSBC | D14: USDCLP | E14: CHILE | F14: 500 | G14: 911.15 | H14: 888.99 | I14: -12463.582 | J14: -0.024320913 | K14: 500000 | L14: -7 | M14: 46027 | N14: 46028
A15: 46013 | B15: HSBC | D15: USDCLP | E15: CHILE | F15: 500 | G15: 906.81 | H15: 888.99 | I15: -10022.61 | J15: -0.019651305 | K15: 500000 | L15: -7 | M15: 46027 | N15: 46028
A16: 46013 | B16: HSBC | D16: USDCLP | E16: CHILE | F16: 500 | G16: 906.56 | H16: 888.99 | I16: -9882.0009 | J16: -0.019380957 | K16: 500000 | L16: -7 | M16: 46027 | N16: 46028
A17: 46013 | B17: HSBC | D17: USDCLP | E17: CHILE | F17: 500 | G17: 905.86 | H17: 888.99 | I17: -9488.2957 | J17: -0.018623187 | K17: 500000 | L17: -7 | M17: 46027 | N17: 46028
A18: 46015 | B18: HSBC | D18: USDCLP | E18: CHILE | F18: -500 | G18: 905.66 | H18: 888.99 | I18: 9375.8085 | J18: -0.018406466 | K18: 500000 | L18: -7 | M18: 46027 | N18: 46028
A19: 46015 | B19: HSBC | D19: USDCLP | E19: CHILE | F19: -500 | G19: 904.13 | H19: 888.99 | I19: 8515.2814 | J19: -0.01674538 | K19: 500000 | L19: -7 | M19: 46027 | N19: 46028
A20: 46024 | B20: HSBC | D20: USDCLP | E20: CHILE | F20: 500 | G20: 899.8 | H20: 888.99 | I20: -6079.9334 | J20: -0.012013781 | K20: 500000 | L20: -7 | M20: 46027 | N20: 46028
I30: 28223.04
H31: SAXO | I31: 0
H32: SCHWAB | I32: 0
H33: CHILE | I33: 0
H34: UBS | I34: 0
H35: SB | I35: 0
A36: TRADING
A39: FECHA | B39: Contraparte | C39: Pos | D39: ticker | E39: País | F39: Monto | G39: Precio Inicial | H39: Precio Cierre | I39: MTM | J39: Rent | K39: Garantía | L39: Plazo | M39: Fix/Exp | N39: Val Date/Settlement
D40: USDCLP | E40: CHILE | H40: 898.49 | I40: 0 | K40: 0 | O40: 0
A41: 46097 | B41: BANCO DE TALCA | D41: USDCLP | E41: CHILE | F41: 1000 | G41: 917.59 | H41: 898.49 | I41: -21.257888 | J41: -0.020815397 | K41: 1000 | L41: -20 | M41: 46105 | N41: 46106 | O41: Vcto x Ocurrir
A42: 46097 | B42: BANCO DE TALCA | D42: USDCLP | E42: CHILE | F42: 1000 | G42: 916.24 | H42: 898.49 | I42: -19.755367 | J42: -0.019372653 | K42: 1000 | L42: -20 | M42: 46105 | N42: 46106 | O42: Vcto x Ocurrir
A43: 46097 | B43: BANCO DE TALCA | D43: USDCLP | E43: CHILE | F43: -500 | G43: 910.73 | H43: 898.49 | I43: 6.8114281 | J43: -0.013439768 | K43: 500 | L43: -20 | M43: 46105 | N43: 46106 | O43: Vcto x Ocurrir
A44: 46097 | B44: BANCO DE TALCA | D44: USDCLP | E44: CHILE | F44: 500 | G44: 908.67 | H44: 898.49 | I44: -5.6650603 | J44: -0.011203187 | K44: 500 | L44: -20 | M44: 46105 | N44: 46106 | O44: Vcto x Ocurrir
A45: 46097 | B45: BANCO DE TALCA | D45: USDCLP | E45: CHILE | F45: -500 | G45: 905.86 | H45: 898.49 | I45: 4.1013256 | J45: -0.008135915 | K45: 500 | L45: -20 | M45: 46105 | N45: 46106 | O45: Vcto x Ocurrir
A46: 46097 | B46: BANCO DE TALCA | D46: USDCLP | E46: CHILE | F46: -500 | G46: 905.86 | H46: 898.49 | I46: 4.1013256 | J46: -0.008135915 | K46: 500 | L46: -20 | M46: 46105 | N46: 46106 | O46: Vcto x Ocurrir
A47: 46097 | B47: BANCO DE TALCA | D47: USDCLP | E47: CHILE | F47: 500 | G47: 909.5 | H47: 898.49 | I47: -6.1269463 | J47: -0.012105553 | K47: 500 | L47: -20 | M47: 46105 | N47: 46106 | O47: Vcto x Ocurrir
A48: 46097 | B48: BANCO DE TALCA | D48: USDCLP | E48: CHILE | F48: 500 | G48: 910.82 | H48: 898.49 | I48: -6.8615121 | J48: -0.013537252 | K48: 500 | L48: -20 | M48: 46105 | N48: 46106 | O48: Vcto x Ocurrir
D49: USDCLP | E49: CHILE | H49: 898.49 | I49: 0 | K49: 0 | O49: 0
D50: USDCLP | E50: CHILE | H50: 898.49 | I50: 0 | K50: 0 | O50: 0
D51: USDCLP | E51: CHILE | H51: 898.49 | I51: 0 | K51: 0 | O51: 0
D52: USDCLP | E52: CHILE | H52: 898.49 | I52: 0 | K52: 0 | O52: 0
D53: USDCLP | E53: CHILE | H53: 898.49 | I53: 0 | K53: 0 | O53: 0
D54: USDCLP | E54: CHILE | H54: 898.49 | I54: 0 | K54: 0 | O54: 0
D55: USDCLP | E55: CHILE | H55: 898.49 | I55: 0 | K55: 0 | O55: 0
D56: USDCLP | E56: CHILE | H56: 898.49 | I56: 0 | K56: 0 | O56: 0
...

Sheet opete
E1: OPCIONES
A5: REALIZADAS
A7: Estado | B7: Contraparte | C7: Pos | D7: ticker | E7: País | F7: Monto | G7: Precio Inicial | H7: Precio Cierre | I7: PRIMAS | J7: STRIKE | K7: Prob. Ocurrencia | L7: Exposición | M7: EXPIRACIÖN | N7: DIAS
A8: 45967 | B8: banco ohiggings | C8: VTA CALL | D8: USDCLP | E8: banco ohiggings | F8: -2000 | G8: 1170 | H8: 941.245 | I8: 2.32 | J8: 0.24303449 | L8: 10000 | M8: 46329 | N8: 363
A9: 45967 | B9: banco ohiggings | C9: VTA CALL | D9: USDCLP | E9: banco ohiggings | F9: -2000 | G9: 1180 | H9: 943.03 | I9: 2.12 | J9: 0.25128575 | L9: 10000 | M9: 46329 | N9: 362
A10: 45971 | B10: banco ohiggings | C10: VTA CALL | D10: USDCLP | E10: banco ohiggings | F10: -2000 | G10: 1160 | H10: 942 | I10: 2.32 | J10: 0.23142251 | L10: 10000 | M10: 46329 | N10: 358
A11: 45978 | B11: banco ohiggings | C11: VTA PUT | D11: USDCLP | E11: banco ohiggings | F11: -2000 | G11: 830 | H11: 920.69 | I11: 3.6 | J11: -0.09850221 | L11: 10000 | M11: 46329 | N11: 352
A12: 46002 | B12: PUP | C12: VTA PUT | D12: QQQ | E12: NASDAQ | F12: -8.5 | G12: 490 | H12: 624.13 | I12: 11.9674 | J12: -0.21490715 | L12: 20825 | M12: 46191 | N12: 189
A13: 46003 | B13: UBS | C13: VTA CALL | D13: AUDUSD | E13: Australia | F13: -1500 | G13: 0.725 | H13: 0.6646 | I13: 0 | J13: 0.090881733 | K13: 0.21216884 | L13: 4984.5 | M13: 46373 | N13: 370
A14: 46003 | B14: UBS | C14: VTA PUT | D14: AUDUSD | E14: Australia | F14: -1500 | G14: 0.615 | H14: 0.6646 | I14: 4.25 | J14: -0.074631357 | K14: 0.24931985 | L14: 4984.5 | M14: 46373 | N14: 370
A15: 46003 | B15: PUP | C15: VTA PUT | D15: SPY | E15: USA | F15: -7.5 | G15: 520 | H15: 683.855 | I15: 6.6594 | J15: -0.23960489 | K15: 0.17269283 | L15: 19500 | M15: 46191 | N15: 188
A16: 46030 | B16: PUP | C16: VTA PUT | D16: GS | E16: GoldmanSachs | F16: -6 | G16: 640 | H16: 937 | I16: 6.5154 | J16: =IF(G16="",0,G16/H16-1) -> -0.31696905 | K16: =IFERROR(#REF!,0) -> 0 | L16: 9.6 | M16: 46191 | N16: =IF(M16="","",M16-TODAY()) -> 66
A17: 46030 | B17: SSCH | C17: VTA PUT | D17: QQQ | E17: NASDAQ | F17: -8.5 | G17: 460 | H17: 621 | I17: 8.075 | J17: =IF(G17="",0,G17/H17-1) -> -0.25925926 | K17: =IFERROR(#REF!,0) -> 0 | L17: 9.775 | M17: 46191 | N17: =IF(M17="","",M17-TODAY()) -> 66
A18: 46034 | B18: PUP | C18: VTA PUT | D18: SPY | E18: USA | F18: -7.5 | G18: 525 | H18: 695.035 | I18: 4.6644 | J18: -0.24464236 | K18: 0.14226847 | L18: 19687.5 | M18: 46191 | N18: 157
A19: 46034 | B19: PUP | C19: VTA PUT | D19: AAPL | E19: AAPL | F19: -7.5 | G19: 190 | H19: 260.66 | I19: 2.0994 | J19: -0.23271695 | K19: 0.15071999 | L19: 7500 | M19: 46191 | N19: 157
A20: 46034 | B20: PUP | C20: VTA PUT | D20: MBbva | E20: MongoBbva | F20: -2 | G20: 280 | H20: 415.235 | I20: 4.5914 | J20: -0.32568305 | K20: 0.057191006 | L20: 2800 | M20: 46191 | N20: 156
A21: 46035 | B21: CS-K | C21: COMPRA PUT | D21: USDCLP | E21: banco ohiggings | F21: 1000 | G21: 830 | H21: 886.675 | I21: -3.1 | J21: -0.063918572 | K21: 0.34232165 | L21: -5000 | M21: 46329 | N21: 294
A22: 46035 | B22: CS-K | C22: VTA PUT | D22: AUDUSD | E22: Australia | F22: -1500 | G22: 0.62 | H22: 0.67035 | I22: 2.2 | J22: -0.075110017 | K22: 0.23745864 | L22: 5027.625 | M22: 46373 | N22: 338
A23: 46035 | B23: PUP | C23: VTA PUT | D23: QQQ | E23: NASDAQ | F23: -8.5 | G23: 370 | H23: 627.29 | I23: 6.1704 | J23: -0.41016117 | K23: 0.13124236 | L23: 15725 | M23: 46374 | N23: 339
A24: 46035 | B24: PUP | C24: VTA PUT | D24: SPY | E24: USA | F24: -6 | G24: 480 | H24: 695.59 | I24: 2.4594 | J24: -0.30993833 | K24: 0.075232142 | L24: 14400 | M24: 46191 | N24: 156
A25: 46035 | B25: PUP | C25: VTA PUT | D25: PUP | E25: Morgan Stanley | F25: -25 | G25: 115 | H25: 184.235 | I25: 3.9488 | J25: -0.37579722 | K25: 0.028844322 | L25: 14375 | M25: 46191 | N25: 156
A26: 46035 | B26: PUP | C26: VTA PUT | D26: JPM | E26: JPM | F26: -7.5 | G26: 235 | H26: 320.77 | I26: 2.9694 | J26: -0.26738785 | K26: 0.10822654 | L26: 8812.5 | M26: 46191 | N26: 156
A27: 46036 | B27: PUP | C27: COMPRA PUT | D27: SPY | E27: USA | F27: -6 | G27: 480 | H27: 690.805 | I27: -3.0126 | J27: -0.30515847 | K27: 0.078533505 | L27: 14400 | M27: 46191 | N27: 155
A28: 46036 | B28: PUP | C28: COMPRA PUT | D28: SPY | E28: USA | F28: -7.5 | G28: 520 | H28: 689.945 | I28: -5.5206 | J28: -0.24631674 | K28: 0.13857602 | L28: 19500 | M28: 46191 | N28: 155
A29: 46036 | B29: CS-K | C29: VTA PUT | D29: SPY | E29: USA | F29: -7.5 | G29: 520 | H29: 689.735 | I29: 5.325 | J29: -0.24608727 | K29: 0.13884793 | L29: 19500 | M29: 46191 | N29: 155
... A62: 46052 | B62: SSCH | C62: VTA PUT | D62: PUPFT | E62: Microsoft | F62: -3.5 | G62: 320 | H62: 437.63 | I62: 5.50326 | J62: -0.2687887 | K62: 0 | L62: 5600 | M62: 46374 | N62: 322
A63: 46052 | B63: NEVASA | C63: VTA CALL | D63: USDCLP | E63: banco ohiggings | F63: -1500 | G63: 910 | H63: 868 | I63: 1.7511521 | J63: =IF(G63="",0,G63/H63-1) -> 0.048387097 | K63: =IFERROR(#REF!,0) -> 0 | L63: 3.75 | M63: 46141 | N63: =IF(M63="","",M63-TODAY()) -> 16
A64: 46059 | B64: SSCH | C64: COMPRA PUT | D64: PUPFT | E64: Microsoft | F64: -4.5 | G64: 370 | H64: 394.615 | I64: 0 | J64: -0.062377254 | K64: 0.36525019 | L64: 8325 | M64: 46191 | N64: 132
A65: 46059 | B65: SSCH | C65: VTA PUT | D65: PUPFT | E65: Microsoft | F65: -4.5 | G65: 300 | H65: 394.695 | I65: -6.156 | J65: -0.23991943 | K65: 0.16802904 | L65: 6750 | M65: 46374 | N65: 315
A66: 46048 | B66: PUP | C66: VTA PUT | D66: PUP | E66: Morgan Stanley | F66: -22.5 | G66: 145 | H66: 167.695 | I66: -25.09935 | J66: -0.13533498 | K66: 0.22481736 | L66: 16312.5 | M66: 46191 | N66: 125
A67: 46066 | B67: PUP | C67: VTA PUT | D67: PUP | E67: Morgan Stanley | F67: -25 | G67: 120 | H67: 170.265 | I67: 21.6494 | J67: -0.29521628 | K67: 0 | L67: 15000 | M67: 46374 | N67: 308
A68: 46006 | B68: SSCH | C68: VTA PUT | D68: MBbva | E68: MongoBbva | F68: -2 | G68: 290 | H68: 308.54 | I68: -16.812 | J68: -0.060089454 | K68: 0.47086035 | L68: 2900 | M68: 46191 | N68: 115
A69: 46076 | B69: SSCH | C69: VTA PUT | D69: TSLA | E69: Tesla | F69: -6 | G69: 220 | H69: 394.665 | I69: 9.9 | J69: -0.44256521 | K69: 0 | L69: 6600 | M69: 46374 | N69: 298
A70: 46015 | B70: SSCH | C70: VTA PUT | D70: PUPFT | E70: Microsoft | F70: -4.5 | G70: 340 | H70: 387.53 | I70: -18.70299 | J70: -0.12264857 | K70: 0.32124329 | L70: 7650 | M70: 46374 | N70: 298
A71: 46034 | B71: PUP | C71: VTA PUT | D71: MBbva | E71: MongoBbva | F71: -2 | G71: 280 | H71: 313.425 | I71: -14.6886 | J71: -0.10664433 | K71: 0.40751128 | L71: 2800 | M71: 46191 | N71: 114
A72: 46077 | B72: PUP | C72: VTA PUT | D72: NVDA | E72: Nvidia | F72: -17.5 | G72: 95 | H72: 199.23 | I72: 8.2944 | J72: -0.52316418 | K72: 0.048886733 | L72: 8312.5 | M72: 46374 | N72: 297
A73: 46077 | B73: PUP | C73: VTA PUT | D73: BAC | E73: Bofa | F73: -37.5 | G73: 42 | H73: 49.975 | I73: -7.7256 | J73: -0.15957979 | K73: 0.15206188 | L73: 15750 | M73: 46191 | N73: 114
A74: 46077 | B74: PUP | C74: VTA PUT | D74: BAC | E74: Bofa | F74: -37.5 | G74: 28 | H74: 49.915 | I74: 3.32865 | J74: -0.43904638 | K74: 0.016949619 | L74: 5250 | M74: 46374 | N74: 297
A75: 46077 | B75: SSCH | C75: VTA PUT | D75: GS | E75: GoldmanSachs | F75: -3.75 | G75: 750 | H75: 897.63 | I75: -16.5 | J75: -0.16446643 | K75: 0.1711005 | L75: 14062.5 | M75: 46191 | N75: 114
... A104: 46100 | B104: SSCH | C104: VTA PUT | D104: META | E104: META | F104: -5 | G104: 360 | H104: 612.965 | I104: 8.115 | J104: -0.41269077 | K104: 0.10136369 | L104: 9000 | M104: 46374 | N104: 274
...

Sheet etf
F4: CARTERA DELTA EQUITY
B7: Fecha | C7: Estado | D7: Contraparte | E7: RSI | F7: ticker | G7: País | H7: Monto | I7: Precio Inicial | J7: Precio Cierre | K7: MTM | L7: Rent | M7: VP
C8: E | F8: FXI | G8: China | I8: 46.11 | K8: =+J8*H8-H8*I8 -> 0 | M8: =+J8*H8 -> 0
C9: E | F9: DBA | G9: Agriculture | I9: 20.185 | J9: 19.6722 | K9: =+J9*H9-H9*I9 -> 0 | L9: =LN(J9/I9) -> -0.025733283 | M9: =+J9*H9 -> 0
C10: E | F10: DB | G10: Deursche Bank | I10: 19.215 | K10: =+J10*H10-H10*I10 -> 0 | M10: =+J10*H10 -> 0
C11: E | F11: LIT | G11: Lithium ETF | I11: 61.89 | J11: 78.915 | K11: =+J11*H11-H11*I11 -> 0 | L11: =LN(J11/I11) -> 0.24301271 | M11: =+J11*H11 -> 0
C12: E | F12: AAPL | G12: Apple | I12: =323.0656/4 -> 80.7664 | K12: =+J12*H12-H12*I12 -> 0 | M12: =+J12*H12 -> 0
C13: E | F13: AAPL | G13: Apple | I13: 123.78987 | K13: =+J13*H13-H13*I13 -> 0 | M13: =+J13*H13 -> 0
C14: E | F14: GLD | G14: ETF Oro | I14: 247.0999 | J14: 432.95 | K14: =+J14*H14-H14*I14 -> 0 | L14: =LN(J14/I14) -> 0.56082954 | M14: =+J14*H14 -> 0
C15: E | F15: GLD | G15: ETF Oro | I15: 248.5491 | J15: 432.95 | K15: =+J15*H15-H15*I15 -> 0 | L15: =LN(J15/I15) -> 0.55498184 | M15: =+J15*H15 -> 0
C16: E | F16: GLD | G16: ETF Oro | I16: 251.615 | J16: 432.95 | K16: =+J16*H16-H16*I16 -> 0 | L16: =LN(J16/I16) -> 0.54272211 | M16: =+J16*H16 -> 0
C17: E | F17: GLD | G17: ETF Oro | I17: 248.9399 | J17: 432.95 | K17: =+J17*H17-H17*I17 -> 0 | L17: =LN(J17/I17) -> 0.55341075 | M17: =+J17*H17 -> 0
C18: E | F18: GLD | G18: ETF Oro | I18: 248.8599 | J18: 432.95 | K18: =+J18*H18-H18*I18 -> 0 | L18: =LN(J18/I18) -> 0.55373216 | M18: =+J18*H18 -> 0
C19: E | F19: QQQ | G19: NASDAQ | I19: 531.5826 | J19: 611.205 | K19: =+J19*H19-H19*I19 -> 0 | L19: =LN(J19/I19) -> 0.13957382 | M19: =+J19*H19 -> 0
C20: E | F20: CRSP | G20: CRISPR THERAPEUTICS AG | I20: 114.8742 | J20: 52.805 | K20: =+J20*H20-H20*I20 -> 0 | L20: =LN(J20/I20) -> -0.77723173 | M20: =+J20*H20 -> 0
C21: E | F21: BABA | G21: Alibaba | I21: 263.75 | K21: =+J21*H21-H21*I21 -> 0 | M21: =+J21*H21 -> 0
C22: E | F22: DIA | G22: DOW JONES | I22: 344.3755 | J22: 476.98 | K22: =+J22*H22-H22*I22 -> 0 | L22: =LN(J22/I22) -> 0.32574193 | M22: =+J22*H22 -> 0
C23: E | F23: DIA | G23: DOW JONES | I23: 338.4971 | J23: 476.98 | K23: =+J23*H23-H23*I23 -> 0 | L23: =LN(J23/I23) -> 0.34295904 | M23: =+J23*H23 -> 0
C24: E | F24: BOTZ | G24: ETF AI | I24: 28.2394 | J24: 35.445 | K24: =+J24*H24-H24*I24 -> 0 | L24: =LN(J24/I24) -> 0.22726403 | M24: =+J24*H24 -> 0
C25: E | F25: BOTZ | G25: ETF AI | I25: 30.9971 | J25: 35.445 | K25: =+J25*H25-H25*I25 -> 0 | L25: =LN(J25/I25) -> 0.13408855 | M25: =+J25*H25 -> 0
C26: E | F26: MDB | G26: MDB | I26: 222.1239 | J26: 231.515 | K26: =+J26*H26-H26*I26 -> 0 | L26: =LN(J26/I26) -> 0.041409332 | M26: =+J26*H26 -> 0
C27: E | F27: AIQ | G27: AIQ | I27: 52.745 | J27: 49.635 | K27: =+J27*H27-H27*I27 -> 0 | L27: =LN(J27/I27) -> -0.060772751 | M27: =+J27*H27 -> 0
C28: E | F28: AIQ | G28: AIQ | I28: 40.6669 | J28: 49.635 | K28: =+J28*H28-H28*I28 -> 0 | L28: =LN(J28/I28) -> 0.19928174 | M28: =+J28*H28 -> 0
C29: E | F29: SPY | G29: S&P500 | I29: 595.1734 | J29: 679.305 | K29: =+J29*H29-H29*I29 -> 0 | L29: =LN(J29/I29) -> 0.13221743 | M29: =+J29*H29 -> 0
C30: E | F30: TSLA | G30: Tesla | I30: 453.65132 | J30: 351.675 | K30: =+J30*H30-H30*I30 -> 0 | L30: =LN(J30/I30) -> -0.25462142 | M30: =+J30*H30 -> 0
C31: E | F31: AMZN | G31: AMZN | I31: 234.8292 | J31: 236.945 | K31: =+J31*H31-H31*I31 -> 0 | L31: =LN(J31/I31) -> 0.0089696053 | M31: =+J31*H31 -> 0
C32: E | F32: NVDA | G32: NVDA | I32: 193.269 | J32: 188.315 | K32: =+J32*H32-H32*I32 -> 0 | L32: =LN(J32/I32) -> -0.025966908 | M32: =+J32*H32 -> 0
C33: E | F33: MSFT | G33: Microsoft | I33: 439.57 | J33: 376.725 | K33: =+J33*H33-H33*I33 -> 0 | L33: =LN(J33/I33) -> -0.1542815 | M33: =+J33*H33 -> 0
... C42: E | F42: NVDA | G42: USA | I42: 130.5197 | J42: 188.315 | K42: =+J42*H42-H42*I42 -> 0 | L42: =LN(J42/I42) -> 0.36659192 | M42: =+J42*H42 -> 0
B43: FIN
J44: Resultado USD | K44: =SUM(K8:K43) -> 0 | M44: =SUM(M8:M43) -> 0
J46: Trading
J47: Cash
J48: TOTAL ETF | M48: =+M46+M44 -> 0
B51: Fecha Aper | C51: Fecha Cierre | D51: Contraparte | E51: Pos | F51: ticker | G51: País | H51: Monto | I51: Precio Inicial | J51: Precio Cierre | K51: MTM
K53: =+J53*H53-H53*I53 -> 0
K54: =+J54*H54-H54*I54 -> 0
K55: =+J55*H55-H55*I55 -> 0
K56: =+J56*H56-H56*I56 -> 0
K57: =+J57*H57-H57*I57 -> 0
...

Sheet Hoja1
G1: SPY
F2: Caida | G2: -0.05
B5: Bid | C5: Ask | D5: mid | E5: Betas | F5: Betas | G5: BETA | H5: Precio Final | I5: Precio Final | K5: beta
A6: CLP= | B6: {=_xll.RDP.Data(A6,"CF_BID")} -> 894.04 | C6: {=_xll.RDP.Data(A6,"CF_ASK")} -> 894.87 | D6: =(B6+C6)/2 -> 894.455 | E6: -0.015 | F6: -0.015 | G6: =IF('ppal B'!$I$11=0,0,IF('ppal B'!$I$11>0,E6*'ppal B'!$I$11*100,F6*'ppal B'!$I$11*100)) -> 0 | H6: 898.375 | I6: =E6*(1+H6) -> -13.490625 | K6: =_xll.RDP.Data(A6,"TR.WACCBeta") -> Unable to resolve all requested identifiers.
A7: BRL= | B7: {=_xll.RDP.Data(A7,"CF_BID")} -> 4.9873 | C7: {=_xll.RDP.Data(A7,"CF_ASK")} -> 4.9882 | D7: =(B7+C7)/2 -> 4.98775 | E7: -0.025 | F7: -0.025 | G7: =IF('ppal B'!$I$11=0,0,IF('ppal B'!$I$11>0,E7*'ppal B'!$I$11*100,F7*'ppal B'!$I$11*100)) -> 0 | H7: 5.0295 | I7: =E7*(1+H7) -> -0.1507375 | K7: =_xll.RDP.Data(A7,"TR.WACCBeta") -> Unable to resolve all requested identifiers.
A8: EUR= | B8: {=_xll.RDP.Data(A8,"CF_BID")} -> 1.1736 | C8: {=_xll.RDP.Data(A8,"CF_ASK")} -> 1.1737 | D8: =(B8+C8)/2 -> 1.17365 | E8: 0.016 | F8: 0.016 | G8: =IF('ppal B'!$I$11=0,0,IF('ppal B'!$I$11>0,E8*'ppal B'!$I$11*100,F8*'ppal B'!$I$11*100)) -> 0 | H8: 1.1716 | I8: =E8*(1+H8) -> 0.0347456 | K8: =_xll.RDP.Data(A8,"TR.WACCBeta") -> Unable to resolve all requested identifiers.
A9: ARKF.K | B9: {=_xll.RDP.Data(A9,"CF_BID")} -> 39.39 | C9: {=_xll.RDP.Data(A9,"CF_ASK")} -> 39.46 | D9: =(B9+C9)/2 -> 39.425 | E9: 0 | F9: 0 | G9: =IF('ppal B'!$I$11=0,0,IF('ppal B'!$I$11>0,E9*'ppal B'!$I$11*100,F9*'ppal B'!$I$11*100)) -> 0 | H9: 39.05 | I9: =E9*(1+H9) -> 0 | K9: =_xll.RDP.Data(A9,"TR.WACCBeta") -> NULL
A10: aud= | B10: {=_xll.RDP.Data(A10,"CF_BID")} -> 0.7088 | C10: {=_xll.RDP.Data(A10,"CF_ASK")} -> 0.7091 | D10: =(B10+C10)/2 -> 0.70895 | E10: 0.01 | F10: 0.01 | G10: =IF('ppal B'!$I$11=0,0,IF('ppal B'!$I$11>0,E10*'ppal B'!$I$11*100,F10*'ppal B'!$I$11*100)) -> 0 | H10: 0.7067 | I10: =E10*(1+H10) -> 0.017067 | K10: =_xll.RDP.Data(A10,"TR.WACCBeta") -> NULL
A11: xau= | B11: {=_xll.RDP.Data(A11,"CF_BID")} -> 4745.46 | C11: {=_xll.RDP.Data(A11,"CF_ASK")} -> 4746.2 | D11: =(B11+C11)/2 -> 4745.83 | E11: 0.02 | F11: 0.01 | G11: =IF('ppal B'!$I$11=0,0,IF('ppal B'!$I$11>0,E11*'ppal B'!$I$11*100,F11*'ppal B'!$I$11*100)) -> 0 | H11: 4720.375 | I11: =E11*(1+H11) -> 94.4275 | K11: =_xll.RDP.Data(A11,"TR.WACCBeta") -> Unable to resolve all requested identifiers.
A12: SPY | B12: {=_xll.RDP.Data(A12,"CF_BID")} -> 682.17 | C12: {=_xll.RDP.Data(A12,"CF_ASK")} -> 682.18 | D12: =(B12+C12)/2 -> 682.175 | E12: 0.01 | F12: 0.01 | G12: =IF('ppal B'!$I$11=0,0,IF('ppal B'!$I$11>0,E12*'ppal B'!$I$11*100,F12*'ppal B'!$I$11*100)) -> 0 | H12: 679.25 | I12: =E12*(1+H12) -> 6.8025 | K12: =_xll.RDP.Data(A12,"TR.WACCBeta") -> NULL
A13: AAPL.O | B13: {=_xll.RDP.Data(A13,"CF_BID")} -> 257.83 | C13: {=_xll.RDP.Data(A13,"CF_ASK")} -> 257.85 | D13: =(B13+C13)/2 -> 257.84 | E13: 0.02 | F13: 0.03 | G13: =IF('ppal B'!$I$11=0,0,IF('ppal B'!$I$11>0,E13*'ppal B'!$I$11*100,F13*'ppal B'!$I$11*100)) -> 0 | H13: 257.4 | I13: =E13*(1+H13) -> 5.168 | K13: =_xll.RDP.Data(A13,"TR.WACCBeta") -> 1.0952454
A14: MXN= | B14: {=_xll.RDP.Data(A14,"CF_BID")} -> 17.2929 | C14: {=_xll.RDP.Data(A14,"CF_ASK")} -> 17.3034 | D14: =(B14+C14)/2 -> 17.29815 | E14: -0.01 | F14: -0.03 | G14: =IF('ppal B'!$I$11=0,0,IF('ppal B'!$I$11>0,E14*'ppal B'!$I$11*100,F14*'ppal B'!$I$11*100)) -> 0 | H14: 17.34315 | I14: =E14*(1+H14) -> -0.1834315 | K14: =_xll.RDP.Data(A14,"TR.WACCBeta") -> Unable to resolve all requested identifiers.
A15: ZAR= | B15: {=_xll.RDP.Data(A15,"CF_BID")} -> 16.4046 | C15: {=_xll.RDP.Data(A15,"CF_ASK")} -> 16.4077 | D15: =(B15+C15)/2 -> 16.40615 | E15: -0.025 | F15: -0.025 | G15: =IF('ppal B'!$I$11=0,0,IF('ppal B'!$I$11>0,E15*'ppal B'!$I$11*100,F15*'ppal B'!$I$11*100)) -> 0 | H15: 16.4854 | I15: =E15*(1+H15) -> -0.437135 | K15: =_xll.RDP.Data(A15,"TR.WACCBeta") -> Unable to resolve all requested identifiers.
A16: JPY= | B16: {=_xll.RDP.Data(A16,"CF_BID")} -> 159.39 | C16: {=_xll.RDP.Data(A16,"CF_ASK")} -> 159.4 | D16: =(B16+C16)/2 -> 159.395 | E16: 0 | F16: 0 | G16: =IF('ppal B'!$I$11=0,0,IF('ppal B'!$I$11>0,E16*'ppal B'!$I$11*100,F16*'ppal B'!$I$11*100)) -> 0 | H16: 159.565 | I16: =E16*(1+H16) -> 0 | K16: =_xll.RDP.Data(A16,"TR.WACCBeta") -> NULL
A17: ARKQ.K | B17: {=_xll.RDP.Data(A17,"CF_BID")} -> 121.21 | C17: {=_xll.RDP.Data(A17,"CF_ASK")} -> 121.31 | D17: =(B17+C17)/2 -> 121.26 | E17: 0 | F17: 0 | G17: =IF('ppal B'!$I$11=0,0,IF('ppal B'!$I$11>0,E17*'ppal B'!$I$11*100,F17*'ppal B'!$I$11*100)) -> 0 | H17: 120.07 | I17: =E17*(1+H17) -> 0 | K17: =_xll.RDP.Data(A17,"TR.WACCBeta") -> NULL
... A71: MRNA.O | B71: {=_xll.RDP.Data(A71,"CF_BID")} -> 51.37 | C71: {=_xll.RDP.Data(A71,"CF_ASK")} -> 51.39 | D71: =(B71+C71)/2 -> 51.38 | E71: 0 | F71: 0 | G71: =IF('ppal B'!$I$11=0,0,IF('ppal B'!$I$11>0,E71*'ppal B'!$I$11*100,F71*'ppal B'!$I$11*100)) -> 0 | H71: 52.335 | I71: =E71*(1+H71) -> 0 | K71: =_xll.RDP.Data(A71,"TR.WACCBeta") -> 1.2050528
A72: TCEHY.PQ | B72: {=_xll.RDP.Data(A72,"CF_BID")} -> 64.18 | C72: {=_xll.RDP.Data(A72,"CF_ASK")} -> 64.23 | D72: =+C72 -> 64.23 | E72: 0 | F72: 0 | G72: =IF('ppal B'!$I$11=0,0,IF('ppal B'!$I$11>0,E72*'ppal B'!$I$11*100,F72*'ppal B'!$I$11*100)) -> 0 | H72: 63.12 | I72: =E72*(1+H72) -> 0 | K72: =_xll.RDP.Data(A72,"TR.WACCBeta") -> 1.3525632
A73: CRSP.O | B73: {=_xll.RDP.Data(A73,"CF_BID")} -> 53.87 | C73: {=_xll.RDP.Data(A73,"CF_ASK")} -> 53.93 | D73: =(B73+C73)/2 -> 53.9 | E73: 0 | F73: 0 | G73: =IF('ppal B'!$I$11=0,0,IF('ppal B'!$I$11>0,E73*'ppal B'!$I$11*100,F73*'ppal B'!$I$11*100)) -> 0 | H73: 52.75 | I73: =E73*(1+H73) -> 0 | K73: =_xll.RDP.Data(A73,"TR.WACCBeta") -> 1.7981445
A74: PYPL.O | B74: {=_xll.RDP.Data(A74,"CF_BID")} -> 47.24 | C74: {=_xll.RDP.Data(A74,"CF_ASK")} -> 47.25 | D74: =(B74+C74)/2 -> 47.245 | E74: 0 | F74: 0 | G74: =IF('ppal B'!$I$11=0,0,IF('ppal B'!$I$11>0,E74*'ppal B'!$I$11*100,F74*'ppal B'!$I$11*100)) -> 0 | H74: 46.195 | I74: =E74*(1+H74) -> 0 | K74: =_xll.RDP.Data(A74,"TR.WACCBeta") -> 1.387552
A75: TSLA.O | B75: {=_xll.RDP.Data(A75,"CF_BID")} -> 353.09 | C75: {=_xll.RDP.Data(A75,"CF_ASK")} -> 353.13 | D75: =(B75+C75)/2 -> 353.11 | E75: 0 | F75: 0 | G75: =IF('ppal B'!$I$11=0,0,IF('ppal B'!$I$11>0,E75*'ppal B'!$I$11*100,F75*'ppal B'!$I$11*100)) -> 0 | H75: 351.485 | I75: =E75*(1+H75) -> 0 | K75: =_xll.RDP.Data(A75,"TR.WACCBeta") -> 1.8855773
A76: SLV | B76: {=_xll.RDP.Data(A76,"CF_BID")} -> 68.08 | C76: {=_xll.RDP.Data(A76,"CF_ASK")} -> 68.09 | D76: =(B76+C76)/2 -> 68.085 | E76: 0 | F76: 0 | G76: =IF('ppal B'!$I$11=0,0,IF('ppal B'!$I$11>0,E76*'ppal B'!$I$11*100,F76*'ppal B'!$I$11*100)) -> 0 | H76: 66.955 | I76: =E76*(1+H76) -> 0 | K76: =_xll.RDP.Data(A76,"TR.WACCBeta") -> NULL
A77: COPX.K | B77: {=_xll.RDP.Data(A77,"CF_BID")} -> 84.47 | C77: {=_xll.RDP.Data(A77,"CF_ASK")} -> 84.52 | D77: =(B77+C77)/2 -> 84.495 | E77: 0 | F77: 0 | G77: =IF('ppal B'!$I$11=0,0,IF('ppal B'!$I$11>0,E77*'ppal B'!$I$11*100,F77*'ppal B'!$I$11*100)) -> 0 | H77: 83.12 | I77: =E77*(1+H77) -> 0 | K77: =_xll.RDP.Data(A77,"TR.WACCBeta") -> NULL
A78: MTLS.O | B78: {=_xll.RDP.Data(A78,"CF_BID")} -> 5.18 | C78: {=_xll.RDP.Data(A78,"CF_ASK")} -> 5.24 | D78: =(B78+C78)/2 -> 5.21 | E78: 0 | F78: 0 | G78: =IF('ppal B'!$I$11=0,0,IF('ppal B'!$I$11>0,E78*'ppal B'!$I$11*100,F78*'ppal B'!$I$11*100)) -> 0 | H78: 5.045 | I78: =E78*(1+H78) -> 0 | K78: =_xll.RDP.Data(A78,"TR.WACCBeta") -> NULL
A79: AVAV.O | B79: {=_xll.RDP.Data(A79,"CF_BID")} -> 191.5 | C79: {=_xll.RDP.Data(A79,"CF_ASK")} -> 191.98 | D79: =(B79+C79)/2 -> 191.74 | E79: 0 | F79: 0 | G79: =IF('ppal B'!$I$11=0,0,IF('ppal B'!$I$11>0,E79*'ppal B'!$I$11*100,F79*'ppal B'!$I$11*100)) -> 0 | H79: 187.055 | I79: =E79*(1+H79) -> 0 | K79: =_xll.RDP.Data(A79,"TR.WACCBeta") -> 1.3983783
A80: xag= | B80: {=_xll.RDP.Data(A80,"CF_BID")} -> 75.52 | C80: {=_xll.RDP.Data(A80,"CF_ASK")} -> 75.6 | D80: =(B80+C80)/2 -> 75.56 | E80: 0 | F80: 0 | G80: =IF('ppal B'!$I$11=0,0,IF('ppal B'!$I$11>0,E80*'ppal B'!$I$11*100,F80*'ppal B'!$I$11*100)) -> 0 | H80: 74.1715 | I80: =E80*(1+H80) -> 0 | K80: =_xll.RDP.Data(A80,"TR.WACCBeta") -> Unable to resolve all requested identifiers.
A81: JD.O | B81: {=_xll.RDP.Data(A81,"CF_BID")} -> 28.67 | C81: {=_xll.RDP.Data(A81,"CF_ASK")} -> 28.68 | D81: =(B81+C81)/2 -> 28.675 | E81: 0 | F81: 0 | G81: =IF('ppal B'!$I$11=0,0,IF('ppal B'!$I$11>0,E81*'ppal B'!$I$11*100,F81*'ppal B'!$I$11*100)) -> 0 | H81: 28.515 | I81: =E81*(1+H81) -> 0 | K81: =_xll.RDP.Data(A81,"TR.WACCBeta") -> 1.5628516
A82: CPER.K | B82: {=_xll.RDP.Data(A82,"CF_BID")} -> 36.71 | C82: {=_xll.RDP.Data(A82,"CF_ASK")} -> 36.73 | D82: =(B82+C82)/2 -> 36.72 | E82: 0 | F82: 0 | G82: =IF('ppal B'!$I$11=0,0,IF('ppal B'!$I$11>0,E82*'ppal B'!$I$11*100,F82*'ppal B'!$I$11*100)) -> 0 | H82: 36.335 | I82: =E82*(1+H82) -> 0 | K82: =_xll.RDP.Data(A82,"TR.WACCBeta") -> NULL
A83: ARCT.O | B83: {=_xll.RDP.Data(A83,"CF_BID")} -> 8.45 | C83: {=_xll.RDP.Data(A83,"CF_ASK")} -> 8.47 | D83: =(B83+C83)/2 -> 8.46 | E83: 0 | F83: 0 | G83: =IF('ppal B'!$I$11=0,0,IF('ppal B'!$I$11>0,E83*'ppal B'!$I$11*100,F83*'ppal B'!$I$11*100)) -> 0 | H83: 8.47 | I83: =E83*(1+H83) -> 0 | K83: =_xll.RDP.Data(A83,"TR.WACCBeta") -> 2.5186186
A84: CGEN.O | B84: {=_xll.RDP.Data(A84,"CF_BID")} -> 2.71 | C84: {=_xll.RDP.Data(A84,"CF_ASK")} -> 2.72 | D84: =(B84+C84)/2 -> 2.715 | E84: 0 | F84: 0 | G84: =IF('ppal B'!$I$11=0,0,IF('ppal B'!$I$11>0,E84*'ppal B'!$I$11*100,F84*'ppal B'!$I$11*100)) -> 0 | H84: 2.615 | I84: =E84*(1+H84) -> 0 | K84: =_xll.RDP.Data(A84,"TR.WACCBeta") -> 2.8519402
... A87: PINS.K | B87: {=_xll.RDP.Data(A87,"CF_BID")} -> 18.03 | C87: {=_xll.RDP.Data(A87,"CF_ASK")} -> 18.04 | D87: =(B87+C87)/2 -> 18.035 | E87: 0 | F87: 0 | G87: =IF('ppal B'!$I$11=0,0,IF('ppal B'!$I$11>0,E87*'ppal B'!$I$11*100,F87*'ppal B'!$I$11*100)) -> 0 | H87: 17.745 | I87: =E87*(1+H87) -> 0 | K87: =_xll.RDP.Data(A87,"TR.WACCBeta") -> 0.90575576
B88: {=_xll.RDP.Data(A88,"CF_BID")} -> No universe defined. | C88: {=_xll.RDP.Data(A88,"CF_ASK")} -> No universe defined. | D88: =(B88+C88)/2 -> #VALUE! | E88: 0 | F88: 0 | G88: =IF('ppal B'!$I$11=0,0,IF('ppal B'!$I$11>0,E88*'ppal B'!$I$11*100,F88*'ppal B'!$I$11*100)) -> 0 | H88: #VALUE! | I88: =E88*(1+H88) -> #VALUE! | K88: =_xll.RDP.Data(A88,"TR.WACCBeta") -> No universe defined.
A89: FVRR.K | B89: {=_xll.RDP.Data(A89,"CF_BID")} -> 10.38 | C89: {=_xll.RDP.Data(A89,"CF_ASK")} -> 10.4 | D89: =(B89+C89)/2 -> 10.39 | E89: 0 | F89: 0 | G89: =IF('ppal B'!$I$11=0,0,IF('ppal B'!$I$11>0,E89*'ppal B'!$I$11*100,F89*'ppal B'!$I$11*100)) -> 0 | H89: 10.065 | I89: =E89*(1+H89) -> 0 | K89: =_xll.RDP.Data(A89,"TR.WACCBeta") -> 1.3835844
A90: SEDG.O | B90: {=_xll.RDP.Data(A90,"CF_BID")} -> 43.82 | C90: {=_xll.RDP.Data(A90,"CF_ASK")} -> 43.9 | D90: =(B90+C90)/2 -> 43.86 | E90: 0 | F90: 0 | G90: =IF('ppal B'!$I$11=0,0,IF('ppal B'!$I$11>0,E90*'ppal B'!$I$11*100,F90*'ppal B'!$I$11*100)) -> 0 | H90: 43.355 | I90: =E90*(1+H90) -> 0 | K90: =_xll.RDP.Data(A90,"TR.WACCBeta") -> 1.3290473
A91: SPNS.O | B91: {=_xll.RDP.Data(A91,"CF_BID")} -> The record could not be found (Error code: 0) | C91: {=_xll.RDP.Data(A91,"CF_ASK")} -> The record could not be found (Error code: 0) | D91: =(B91+C91)/2 -> #VALUE! | E91: 0 | F91: 0 | G91: =IF('ppal B'!$I$11=0,0,IF('ppal B'!$I$11>0,E91*'ppal B'!$I$11*100,F91*'ppal B'!$I$11*100)) -> 0 | H91: #VALUE! | I91: =E91*(1+H91) -> #VALUE! | K91: =_xll.RDP.Data(A91,"TR.WACCBeta") -> NULL
B92: {=_xll.RDP.Data(A92,"CF_BID")} -> No universe defined. | C92: {=_xll.RDP.Data(A92,"CF_ASK")} -> No universe defined. | D92: =(B92+C92)/2 -> #VALUE! | E92: 0 | F92: 0 | G92: =IF('ppal B'!$I$11=0,0,IF('ppal B'!$I$11>0,E92*'ppal B'!$I$11*100,F92*'ppal B'!$I$11*100)) -> 0 | H92: #VALUE! | I92: =E92*(1+H92) -> #VALUE! | K92: =_xll.RDP.Data(A92,"TR.WACCBeta") -> No universe defined.
A93: CAMT.O | B93: {=_xll.RDP.Data(A93,"CF_BID")} -> 173.35 | C93: {=_xll.RDP.Data(A93,"CF_ASK")} -> 174.97 | D93: =(B93+C93)/2 -> 174.16 | E93: 0 | F93: 0 | G93: =IF('ppal B'!$I$11=0,0,IF('ppal B'!$I$11>0,E93*'ppal B'!$I$11*100,F93*'ppal B'!$I$11*100)) -> 0 | H93: 173.28 | I93: =E93*(1+H93) -> 0 | K93: =_xll.RDP.Data(A93,"TR.WACCBeta") -> 1.5800617
A94: ADSK.O | B94: {=_xll.RDP.Data(A94,"CF_BID")} -> 226.38 | C94: {=_xll.RDP.Data(A94,"CF_ASK")} -> 226.51 | D94: =(B94+C94)/2 -> 226.445 | E94: 0 | F94: 0 | G94: =IF('ppal B'!$I$11=0,0,IF('ppal B'!$I$11>0,E94*'ppal B'!$I$11*100,F94*'ppal B'!$I$11*100)) -> 0 | H94: 222.325 | I94: =E94*(1+H94) -> 0 | K94: =_xll.RDP.Data(A94,"TR.WACCBeta") -> 1.3946633
B95: {=_xll.RDP.Data(A95,"CF_BID")} -> No universe defined. | C95: {=_xll.RDP.Data(A95,"CF_ASK")} -> No universe defined. | D95: =(B95+C95)/2 -> #VALUE! | E95: 0 | F95: 0 | G95: =IF('ppal B'!$I$11=0,0,IF('ppal B'!$I$11>0,E95*'ppal B'!$I$11*100,F95*'ppal B'!$I$11*100)) -> 0 | H95: #VALUE! | I95: =E95*(1+H95) -> #VALUE! | K95: =_xll.RDP.Data(A95,"TR.WACCBeta") -> No universe defined.
A96: AUDC.O | B96: {=_xll.RDP.Data(A96,"CF_BID")} -> 8.86 | C96: {=_xll.RDP.Data(A96,"CF_ASK")} -> 8.93 | D96: =(B96+C96)/2 -> 8.895 | E96: 0 | F96: 0 | G96: =IF('ppal B'!$I$11=0,0,IF('ppal B'!$I$11>0,E96*'ppal B'!$I$11*100,F96*'ppal B'!$I$11*100)) -> 0 | H96: 8.865 | I96: =E96*(1+H96) -> 0 | K96: =_xll.RDP.Data(A96,"TR.WACCBeta") -> 0.94782491
A97: CDNA.O | B97: {=_xll.RDP.Data(A97,"CF_BID")} -> 16.51 | C97: {=_xll.RDP.Data(A97,"CF_ASK")} -> 16.56 | D97: =(B97+C97)/2 -> 16.535 | E97: 0 | F97: 0 | G97: =IF('ppal B'!$I$11=0,0,IF('ppal B'!$I$11>0,E97*'ppal B'!$I$11*100,F97*'ppal B'!$I$11*100)) -> 0 | H97: 16.335 | I97: =E97*(1+H97) -> 0 | K97: =_xll.RDP.Data(A97,"TR.WACCBeta") -> 2.4689168
...

Sheet UF
A6: Fecha | B6: Contraparte | C6: Monto UF | D6: Tasa Spot | E6: Dif Inicial | F6: vto | G6: Días | H6: Precio Cierre | I6: MTM
A7: 45848 | B7: BCI | C7: 30000 | D7: 0.0332 | E7: 3.0388 | J7: =3.39-3.08 -> 0.31
C26: =SUM(C7:C25) -> 30000 | I26: =SUM(I7:I20) -> 0
A31: REALIZADO
A33: Fecha | B33: Contraparte | C33: Monto UF | D33: Tasa Spot | E33: Precio Inicial | F33: vto | G33: Días | H33: Precio Cierre | I33: MTM
I45: =SUM(I34:I44) -> 0

Sheet t10y
D1: FUTUROS T10Y
A4: REALIZADO
A6: Instumento | B6: fecha | C6: Contraparte | D6: Pos | E6: ytm inicial | F6: ytm merc | G6: Precio Inicial | H6: vto | I6: Precio Cierre | J6: result | K6: fecha cierre | L6: EXP
A7: WNH6 | C7: CS-K | E7: 0.0493 | F7: 0.0485 | G7: 116.34375 | H7: =G7*1000*D7 -> 0 | I7: 117.65625 | J7: =(I7-G7)*D7*1000 -> 0
J48: =SUM(J7:J47) -> 0
A55: Instumento | B55: fecha | C55: Contraparte | D55: Pos | E55: ytm inicial | F55: ytm merc | G55: Precio Inicial | H55: vto | I55: Precio Cierre | J55: result | K55: fecha cierre
A56: WNH6 | B56: 45992 | C56: CS-K | D56: 9 | G56: 119.59375 | H56: 1076343.8 | I56: 118.65625 | J56: -8437.5 | K56: 46036
A57: WNH6 | B57: 46042 | C57: CS-K | D57: 5 | E57: 0.0493 | F57: 0.0485 | G57: 116.34375 | H57: 581718.75 | I57: 117.65625 | J57: 6562.5 | K57: 46044
D87: =SUM(D56:D86) -> 14 | J87: =SUM(J56:J86) -> -1875

Sheet cartera
A1: CARTERA RENTA FIJA
A3: BANCO | B3: ISIN | C3: Name | D3: Monto Compra | E3: Coupon | F3: Maturity | G3: PRECIO COMPRA | H3: Precio 31-Dic-2021 | I3: Precio 31-Dic-2025 | J3: Precio Mercado (29-05) | K3: CurrYield | L3: YLD_YTM_ask | M3: DUR_MID | N3: rtg_sp | O3: rtg_moody | P3: rtg_fitch | Q3: industry_subgroup | R3: PAIS | S3: crncy | T3: callable | U3: NXT_CALL_DT | V3: payment_rank | W3: Monto Compra | X3: Costo | Y3: status | Z3: VP | AA3: MTM | AB3: MTM trib | AC3: VPxYTM | AD3: VPxDur | AE3: Rt % año | AF3: INTERESES x AÑO | AG3: FECHA COMPRA | AH3: VENTA | AI3: compra | AJ3: LTV | AK3: LTV usd
A4: SCH | B4: XS145DGFDJHDKJ | C4: bono1 | D4: 588.23529 | E4: 1.5 | F4: 31-07-2040 | G4: 106 | H4: 29.433 | I4: 64.825 | J4: 57.908 | K4: =IF(AF4="","",AF4/Z4) -> 0.025903157 | L4: 13.423314 | M4: 7.4970215 | N4: NR | O4: #N/A N/A | P4: WD | Q4: Sovereign | R4: EC | S4: USD | T4: SINKABLE | V4: Sr Unsecured | W4: =+D4*G4/100 -> 623.52941 | X4: =+D4*G4/100 -> 623.52941 | Z4: =+D4*J4/100 -> 340.63529 | AA4: =IF(+I4=0,AB4,D4*(J4-I4)/100) -> -40.688235 | AB4: =+$D4*($J4-$G4)/100 -> -282.89412 | AC4: =+Z4*L4 -> 4572.4547 | AD4: =+Z4*M4 -> 2553.7501 | AE4: =+AA4/X4 -> -0.065254717 | AF4: =+D4*E4/100 -> 8.8235294 | AJ4: 0 | AK4: =AJ4*Z4 -> 0
A5: SCH | B5: XS145DGFDJHDKJ | C5: bono2 | D5: 32352.941 | E5: 0 | F5: 46177 | G5: 98.236688 | I5: 98.5194 | J5: 98.881 | K5: =IF(AF5="","",AF5/Z5) -> 0.037029686 | L5: 3.6615324 | M5: 0.30684932 | N5: #N/A N/A | O5: #N/A N/A | P5: #N/A N/A | Q5: Sovereign | R5: US | S5: USD | T5: NORMAL | V5: Unsecured | W5: =+D5*G5/100 -> 31782.458 | X5: =+D5*G5/100 -> 31782.458 | Z5: =+D5*J5/100 -> 31990.912 | AA5: =IF(+I5=0,AB5,D5*(J5-I5)/100) -> 116.98824 | AB5: =+$D5*($J5-$G5)/100 -> 208.45404 | AC5: =+Z5*L5 -> 117135.76 | AD5: =+Z5*M5 -> 9816.3894 | AE5: =+AA5/X5 -> 0.0036809059 | AF5: =+D5*L5/100 -> 1184.6134 | AJ5: 0.95 | AK5: =AJ5*Z5 -> 30391.366
A6: SCH | B6: XS145DGFDJHDKJ | C6: bono3 | D6: 1544.1176 | E6: 0 | F6: 46177 | G6: 98.24 | I6: 98.5194 | J6: 98.881 | K6: =IF(AF6="","",AF6/Z6) -> 0.037029686 | L6: 3.6615324 | M6: 0.30684932 | N6: #N/A N/A | O6: #N/A N/A | P6: #N/A N/A | Q6: Sovereign | R6: US | S6: USD | T6: NORMAL | V6: Unsecured | W6: =+D6*G6/100 -> 1516.9412 | X6: =+D6*G6/100 -> 1516.9412 | Z6: =+D6*J6/100 -> 1526.839 | AA6: =IF(+I6=0,AB6,D6*(J6-I6)/100) -> 5.5835294 | AB6: =+$D6*($J6-$G6)/100 -> 9.8977941 | AC6: =+Z6*L6 -> 5590.5703 | AD6: =+Z6*M6 -> 468.50949 | AE6: =+AA6/X6 -> 0.0036807818 | AF6: =+D6*L6/100 -> 56.538367 | AG6: 45120 | AJ6: 0.95 | AK6: =AJ6*Z6 -> 1450.497 | AN6: LTV RF
A7: SCH | B7: XS145DGFDJHDKJ | C7: bono4 | D7: 1973.5294 | E7: 0 | F7: 46177 | G7: 98.236 | I7: 98.5194 | J7: 98.881 | K7: =IF(AF7="","",AF7/Z7) -> 0.037029686 | L7: 3.6615324 | M7: 0.30684932 | N7: #N/A N/A | O7: #N/A N/A | P7: #N/A N/A | Q7: Sovereign | R7: US | S7: USD | T7: NORMAL | V7: Unsecured | W7: =+D7*G7/100 -> 1938.7164 | X7: =+D7*G7/100 -> 1938.7164 | Z7: =+D7*J7/100 -> 1951.4456 | AA7: =IF(+I7=0,AB7,D7*(J7-I7)/100) -> 7.1362824 | AB7: =+$D7*($J7-$G7)/100 -> 12.729265 | AC7: =+Z7*L7 -> 7145.2813 | AD7: =+Z7*M7 -> 598.79975 | AE7: =+AA7/X7 -> 0.0036809316 | AF7: =+D7*L7/100 -> 72.261418 | AG7: 45120 | AJ7: 0.95 | AK7: =AJ7*Z7 -> 1853.8733 | AM7: DB | AN7: =SUMIF($A$4:$A$25,AM7,$AK$4:$AK$25) -> 0
A8: SCH | B8: XS145DGFDJHDKJ | C8: bono5 | D8: 764.70588 | E8: 0 | F8: 46177 | G8: 98.1886 | I8: 98.5194 | J8: 98.881 | K8: =IF(AF8="","",AF8/Z8) -> 0.037029686 | L8: 3.6615324 | M8: 0.30684932 | N8: #N/A N/A | O8: #N/A N/A | P8: #N/A N/A | Q8: Sovereign | R8: US | S8: USD | T8: NORMAL | V8: Unsecured | W8: =+D8*G8/100 -> 750.854 | X8: =+D8*G8/100 -> 750.854 | Z8: =+D8*J8/100 -> 756.14882 | AA8: =IF(+I8=0,AB8,D8*(J8-I8)/100) -> 2.7651765 | AB8: =+$D8*($J8-$G8)/100 -> 5.2948235 | AC8: =+Z8*L8 -> 2768.6634 | AD8: =+Z8*M8 -> 232.02375 | AE8: =+AA8/X8 -> 0.0036827086 | AF8: =+D8*L8/100 -> 27.999953 | AJ8: 0.85 | AK8: =AJ8*Z8 -> 642.7265 | AM8: MS-K | AN8: =SUMIF($A$4:$A$25,AM8,$AK$4:$AK$25) -> 0
A9: SCH | B9: XS145DGFDJHDKJ | C9: bono6 | D9: 17264.706 | E9: 0 | F9: 46177 | G9: 98.255083 | I9: 98.5194 | J9: 98.881 | K9: =IF(AF9="","",AF9/Z9) -> 0.037029686 | L9: 3.6615324 | M9: 0.30684932 | N9: #N/A N/A | O9: #N/A N/A | P9: #N/A N/A | Q9: Sovereign | R9: US | S9: USD | T9: NORMAL | V9: Unsecured | W9: =+D9*G9/100 -> 16963.451 | X9: =+D9*G9/100 -> 16963.451 | Z9: =+D9*J9/100 -> 17071.514 | AA9: =IF(+I9=0,AB9,D9*(J9-I9)/100) -> 62.429176 | AB9: =+$D9*($J9-$G9)/100 -> 108.06273 | AC9: =+Z9*L9 -> 62507.9 | AD9: =+Z9*M9 -> 5238.3823 | AE9: =+AA9/X9 -> 0.0036802167 | AF9: =+D9*L9/100 -> 632.15279 | AJ9: 0.99 | AK9: =AJ9*Z9 -> 16900.799 | AM9: MS | AN9: =SUMIF($A$4:$A$25,AM9,$AK$4:$AK$25) -> 0
A10: SCH | B10: XS145DGFDJHDKJ | C10: bono7 | D10: 794.11765 | E10: 0 | F10: 46177 | G10: 98.191375 | I10: 98.5194 | J10: 98.881 | K10: =IF(AF10="","",AF10/Z10) -> 0.037029686 | L10: 3.6615324 | M10: 0.30684932 | N10: #N/A N/A | O10: #N/A N/A | P10: #N/A N/A | Q10: Sovereign | R10: US | S10: USD | T10: NORMAL | V10: Unsecured | W10: =+D10*G10/100 -> 779.75504 | X10: =+D10*G10/100 -> 779.75504 | Z10: =+D10*J10/100 -> 785.23147 | AA10: =IF(+I10=0,AB10,D10*(J10-I10)/100) -> 2.8715294 | AB10: =+$D10*($J10-$G10)/100 -> 5.4764338 | AC10: =+Z10*L10 -> 2875.1504 | AD10: =+Z10*M10 -> 240.94774 | AE10: =+AA10/X10 -> 0.0036826045 | AF10: =+D10*L10/100 -> 29.076875 | AG10: 45120 | AJ10: 0.95 | AK10: =AJ10*Z10 -> 745.9699 | AM10: UBS-H | AN10: =SUMIF($A$4:$A$25,AM10,$AK$4:$AK$25) -> 0
A11: SCH | B11: XS145DGFDJHDKJ | C11: bono8 | D11: 1823.5294 | E11: 0 | F11: 46177 | G11: 99.07175 | I11: 98.5194 | J11: 99.07175 | K11: =IF(AF11="","",AF11/Z11) -> 0.03695839 | L11: 3.6615324 | M11: 0.30684932 | N11: #N/A N/A | O11: #N/A N/A | P11: #N/A N/A | Q11: Sovereign | R11: US | S11: USD | T11: NORMAL | V11: Unsecured | W11: =+D11*G11/100 -> 1806.6025 | X11: =+D11*G11/100 -> 1806.6025 | Z11: =+D11*J11/100 -> 1806.6025 | AA11: =IF(+I11=0,AB11,D11*(J11-I11)/100) -> 10.072265 | AB11: =+$D11*($J11-$G11)/100 -> 0 | AC11: =+Z11*L11 -> 6614.9335 | AD11: =+Z11*M11 -> 554.35474 | AE11: =+AA11/X11 -> 0.0055752523 | AF11: =+D11*L11/100 -> 66.769119 | AG11: 45120 | AJ11: 0.95 | AK11: =AJ11*Z11 -> 1716.2724 | AM11: UBS-H | AN11: =SUMIF($A$4:$A$25,AM11,$AK$4:$AK$25) -> 0
A12: SCH | B12: XS145DGFDJHDKJ | C12: bono9 | D12: 97.058824 | E12: 8.25 | F12: 17-01-2034 | G12: 98.51 | H12: 119.22 | I12: 120.489 | J12: 120.197 | K12: =IF(AF12="","",AF12/Z12) -> 0.06863732 | L12: 5.0995894 | M12: 6.1421473 | N12: BBB- | O12: Baa3 | P12: BBB | Q12: Metal-Iron | R12: BR | S12: USD | T12: AT MATURITY | V12: Sr Unsecured | W12: =+D12*G12/100 -> 95.612647 | X12: =+D12*G12/100 -> 95.612647 | Z12: =+D12*J12/100 -> 116.66179 | AA12: =IF(+I12=0,AB12,D12*(J12-I12)/100) -> -0.28341176 | AB12: =+$D12*($J12-$G12)/100 -> 21.049147 | AC12: =+Z12*L12 -> 594.92725 | AD12: =+Z12*M12 -> 716.55393 | AE12: =+AA12/X12 -> -0.0029641661 | AF12: =+D12*E12/100 -> 8.0073529 | AK12: =AJ12*Z12 -> 0
A13: SCH | B13: XS145DGFDJHDKJ | C13: bono10 | D13: 147.05882 | E13: 6.95 | F13: 07-13-2027 | G13: 101.6 | H13: 70.768 | I13: 100.773 | J13: 100.977 | K13: =IF(AF13="","",AF13/Z13) -> 0.068827555 | L13: 6.0445878 | M13: 1.3921988 | N13: CCC+ | O13: #N/A N/A | P13: CCC- | Q13: Oil Comp-Integrated | R13: AR | S13: USD | T13: AT MATURITY | V13: Sr Unsecured | W13: =+D13*G13/100 -> 149.41176 | X13: =+D13*G13/100 -> 149.41176 | Z13: =+D13*J13/100 -> 148.49559 | AA13: =IF(+I13=0,AB13,D13*(J13-I13)/100) -> 0.3 | AB13: =+$D13*($J13-$G13)/100 -> -0.91617647 | AC13: =+Z13*L13 -> 897.59463 | AD13: =+Z13*M13 -> 206.73538 | AE13: =+AA13/X13 -> 0.002007874 | AF13: =+D13*E13/100 -> 10.220588 | AJ13: 0 | AK13: =AJ13*Z13 -> 0
A14: SCH | B14: XS145DGFDJHDKJ | C14: bono11 | D14: 1470.5882 | E14: 5.75 | F14: 54001 | G14: 74.45 | I14: 82.12 | J14: 82.099 | K14: =IF(AF14="","",AF14/Z14) -> 0.070037394 | L14: 7.4247526 | M14: 11.400297 | O14: B3 | P14: B | Q14: Sovereign | R14: TR | S14: USD | V14: Sr Unsecured | W14: =+D14*G14/100 -> 1094.8529 | X14: =+D14*G14/100 -> 1094.8529 | Z14: =+D14*J14/100 -> 1207.3382 | AA14: =IF(+I14=0,AB14,D14*(J14-I14)/100) -> -0.30882353 | AB14: =+$D14*($J14-$G14)/100 -> 112.48529 | AC14: =+Z14*L14 -> 8964.1877 | AD14: =+Z14*M14 -> 13764.015 | AE14: =+AA14/X14 -> -0.0002820685 | AF14: =+D14*E14/100 -> 84.558824 | AJ14: 0 | AK14: =AJ14*Z14 -> 0
A15: SCH | B15: XS145DGFDJHDKJ | C15: bono12 | D15: 2941.1765 | E15: 7.5 | F15: Perpetuo | G15: 102.15 | I15: 106.241 | J15: 106.786 | K15: =IF(AF15="","",AF15/Z15) -> 0.070233926 | L15: 7.0608097 | M15: 6.5089424 | N15: BB+ | O15: Ba1 | Q15: Banks | R15: CL | S15: USD | T15: CALLABLE | V15: Jr Subordinated | W15: =+D15*G15/100 -> 3004.4118 | X15: =+D15*G15/100 -> 3004.4118 | Z15: =+D15*J15/100 -> 3140.7647 | AA15: =IF(+I15=0,AB15,D15*(J15-I15)/100) -> 16.029412 | AB15: =+$D15*($J15-$G15)/100 -> 136.35294 | AC15: =+Z15*L15 -> 22176.342 | AD15: =+Z15*M15 -> 20443.056 | AE15: =+AA15/X15 -> 0.0053352912 | AF15: =+D15*E15/100 -> 220.58824 | AJ15: 0.6 | AK15: =AJ15*Z15 -> 1884.4588
A16: SCH | B16: XS145DGFDJHDKJ | C16: bono13 | D16: 970.58824 | E16: 8.25 | F16: 20-01-2034 | G16: 127.625 | H16: 112.492 | I16: 116.286 | J16: 115.558 | K16: =IF(AF16="","",AF16/Z16) -> 0.071392721 | L16: 5.7538904 | M16: 6.1098108 | N16: BB- | O16: Ba2 | P16: BB- | Q16: Sovereign | R16: BR | S16: USD | T16: AT MATURITY | V16: Sr Unsecured | W16: =+D16*G16/100 -> 1238.7132 | X16: =+D16*G16/100 -> 1238.7132 | Z16: =+D16*J16/100 -> 1121.5924 | AA16: =IF(+I16=0,AB16,D16*(J16-I16)/100) -> -7.0658824 | AB16: =+$D16*($J16-$G16)/100 -> -117.12088 | AC16: =+Z16*L16 -> 6453.5194 | AD16: =+Z16*M16 -> 6852.7171 | AE16: =+AA16/X16 -> -0.0057042116 | AF16: =+D16*E16/100 -> 80.073529 | AJ16: 0.55 | AK16: =AJ16*Z16 -> 616.87579
A17: SCH | B17: XS145DGFDJHDKJ | C17: bono14 | D17: 1470.5882 | E17: 7.625 | F17: 47855 | G17: 101.901 | I17: 105.26 | J17: 105.045 | K17: =IF(AF17="","",AF17/Z17) -> 0.072587939 | L17: 6.3821658 | M17: 3.0507515 | N17: BBB- | O17: Ba2 | P17: BB+ | Q17: Líneas Aéreas | R17: CL | S17: USD | T17: CALLABLE | V17: Secured | W17: =+D17*G17/100 -> 1498.5441 | X17: =+D17*G17/100 -> 1498.5441 | Z17: =+D17*J17/100 -> 1544.7794 | AA17: =IF(+I17=0,AB17,D17*(J17-I17)/100) -> -3.1617647 | AB17: =+$D17*($J17-$G17)/100 -> 46.235294 | AC17: =+Z17*L17 -> 9859.0383 | AD17: =+Z17*M17 -> 4712.7381 | AE17: =+AA17/X17 -> -0.002109891 | AF17: =+D17*E17/100 -> 112.13235 | AJ17: 0.55 | AK17: =AJ17*Z17 -> 849.62868
A18: SCH | B18: XS145DGFDJHDKJ | C18: bono15 | D18: 194.11765 | E18: 8.6 | F18: 15-12-2030 | G18: 146 | H18: 121.59 | I18: 117.411 | J18: 117.539 | K18: =IF(AF18="","",AF18/Z18) -> 0.073167204 | L18: 4.4734589 | M18: 4.0866908 | N18: A- | O18: A2 | P18: WD | Q18: Property/Casualty Ins | R18: FR | S18: USD | T18: AT MATURITY | V18: Subordinated | W18: =+D18*G18/100 -> 283.41176 | X18: =+D18*G18/100 -> 283.41176 | Z18: =+D18*J18/100 -> 228.16394 | AA18: =IF(+I18=0,AB18,D18*(J18-I18)/100) -> 0.24847059 | AB18: =+$D18*($J18-$G18)/100 -> -55.247824 | AC18: =+Z18*L18 -> 1020.682 | AD18: =+Z18*M18 -> 932.43548 | AE18: =+AA18/X18 -> 0.00087671233 | AF18: =+D18*E18/100 -> 16.694118 | AK18: =AJ18*Z18 -> 0
A19: SCH | B19: XS145DGFDJHDKJ | C19: bono16 | D19: 882.35294 | E19: 6.5 | F19: 02-06-2041 | G19: 74.167 | H19: 65.698 | I19: 86.682 | J19: 88.498 | K19: =IF(AF19="","",AF19/Z19) -> 0.073447988 | L19: 7.7798601 | M19: 9.4231421 | N19: BBB | O19: B1 | P19: BB-u | Q19: Oil Comp-Integrated | R19: MX | S19: USD | T19: AT MATURITY | V19: Sr Unsecured | W19: =+D19*G19/100 -> 654.41471 | X19: =+D19*G19/100 -> 654.41471 | Z19: =+D19*J19/100 -> 780.86471 | AA19: =IF(+I19=0,AB19,D19*(J19-I19)/100) -> 16.023529 | AB19: =+$D19*($J19-$G19)/100 -> 126.45 | AC19: =+Z19*L19 -> 6075.0181 | AD19: =+Z19*M19 -> 7358.1991 | AE19: =+AA19/X19 -> 0.024485283 | AF19: =+D19*E19/100 -> 57.352941 | AJ19: 0.5 | AK19: =AJ19*Z19 -> 390.43235
A20: SCH | B20: XS145DGFDJHDKJ | C20: bono17 | D20: 294.11765 | E20: 6.5 | F20: 02-06-2041 | G20: 74.167 | H20: 65.698 | I20: 86.682 | J20: 88.498 | K20: =IF(AF20="","",AF20/Z20) -> 0.073447988 | L20: 7.7798601 | M20: 9.4231421 | N20: BBB | O20: B1 | P20: BB-u | Q20: Oil Comp-Integrated | R20: MX | S20: USD | T20: AT MATURITY | V20: Sr Unsecured | W20: =+D20*G20/100 -> 218.13824 | X20: =+D20*G20/100 -> 218.13824 | Z20: =+D20*J20/100 -> 260.28824 | AA20: =IF(+I20=0,AB20,D20*(J20-I20)/100) -> 5.3411765 | AB20: =+$D20*($J20-$G20)/100 -> 42.15 | AC20: =+Z20*L20 -> 2025.006 | AD20: =+Z20*M20 -> 2452.733 | AE20: =+AA20/X20 -> 0.024485283 | AF20: =+D20*E20/100 -> 19.117647 | AJ20: 0.55 | AK20: =AJ20*Z20 -> 143.15853
A21: SCH | B21: XS145DGFDJHDKJ | C21: bono18 | D21: 291.17647 | E21: 6.5 | F21: 02-06-2041 | G21: 100.65 | H21: 65.698 | I21: 86.682 | J21: 88.498 | K21: =IF(AF21="","",AF21/Z21) -> 0.073447988 | L21: 7.7798601 | M21: 9.4231421 | N21: BBB | O21: B1 | P21: BB-u | Q21: Oil Comp-Integrated | R21: MX | S21: USD | T21: AT MATURITY | V21: Sr Unsecured | W21: =+D21*G21/100 -> 293.06912 | X21: =+D21*G21/100 -> 293.06912 | Z21: =+D21*J21/100 -> 257.68535 | AA21: =IF(+I21=0,AB21,D21*(J21-I21)/100) -> 5.2877647 | AB21: =+$D21*($J21-$G21)/100 -> -35.383765 | AC21: =+Z21*L21 -> 2004.756 | AD21: =+Z21*M21 -> 2428.2057 | AE21: =+AA21/X21 -> 0.018042722 | AF21: =+D21*E21/100 -> 18.926471 | AK21: =AJ21*Z21 -> 0
A22: SCH | B22: XS145DGFDJHDKJ | C22: bono19 | D22: 429.41176 | E22: 10.75 | F22: 01-08-2039 | G22: 165.5 | H22: 133.03 | I22: 133.254 | J22: 133.125 | K22: =IF(AF22="","",AF22/Z22) -> 0.080751174 | L22: 6.9017989 | M22: 6.1441006 | N22: BBB | O22: Baa2 | P22: BBB | Q22: Multi-line Insurance | R22: US | S22: USD | T22: CALL/EXT | V22: Jr Subordinated | W22: =+D22*G22/100 -> 710.67647 | X22: =+D22*G22/100 -> 710.67647 | Z22: =+D22*J22/100 -> 571.65441 | AA22: =IF(+I22=0,AB22,D22*(J22-I22)/100) -> -0.55394118 | AB22: =+$D22*($J22-$G22)/100 -> -139.02206 | AC22: =+Z22*L22 -> 3945.4438 | AD22: =+Z22*M22 -> 3512.3022 | AE22: =+AA22/X22 -> -0.00077945619 | AF22: =+D22*E22/100 -> 46.161765 | AK22: =AJ22*Z22 -> 0
A23: SCH | B23: XS145DGFDJHDKJ | C23: bono20 | D23: 588.23529 | E23: 7.25 | F23: 30-06-2031 | G23: 103.582 | H23: 82.581 | I23: 88.052 | J23: 84.706 | K23: =IF(AF23="","",AF23/Z23) -> 0.085590159 | L23: 11.061985 | M23: 3.7589709 | N23: #N/A N/A | O23: Ba3 | P23: BB- | Q23: Oil Refining&Marketing | R23: BR | S23: USD | T23: SINKABLE | V23: Secured | W23: =+D23*G23/100 -> 609.30588 | X23: =+D23*G23/100 -> 609.30588 | Z23: =+D23*J23/100 -> 498.27059 | AA23: =IF(+I23=0,AB23,D23*(J23-I23)/100) -> -19.682353 | AB23: =+$D23*($J23-$G23)/100 -> -111.03529 | AC23: =+Z23*L23 -> 5511.8616 | AD23: =+Z23*M23 -> 1872.9847 | AF23: =+D23*E23/100 -> 42.647059 | AJ23: 0.6 | AK23: =AJ23*Z23 -> 298.96235
A24: SCH | B24: XS145DGFDJHDKJ | C24: bono21 | D24: 291.17647 | E24: 6.625 | F24: #N/A Field Not Applicable | G24: 104.88 | H24: 57.39 | I24: 74.284 | J24: 75.03 | K24: =IF(AF24="","",AF24/Z24) -> 0.088298014 | L24: 8.7924846 | M24: 11.501221 | N24: BBB | O24: B1 | P24: BB-u | Q24: Oil Comp-Integrated | R24: MX | S24: USD | T24: PERP/CALL | V24: Sr Unsecured | W24: =+D24*G24/100 -> 305.38588 | X24: =+D24*G24/100 -> 305.38588 | Z24: =+D24*J24/100 -> 218.46971 | AA24: =IF(+I24=0,AB24,D24*(J24-I24)/100) -> 2.1721765 | AB24: =+$D24*($J24-$G24)/100 -> -86.916176 | AC24: =+Z24*L24 -> 1920.8915 | AD24: =+Z24*M24 -> 2512.6683 | AE24: =+AA24/X24 -> 0.0071128909 | AF24: =+D24*E24/100 -> 19.290441 | AG24: 45099 | AJ24: 0.5 | AK24: =AJ24*Z24 -> 109.23485
A25: SCH | B25: XS145DGFDJHDKJ | C25: bono22 | D25: 1470.5882 | E25: 9.625 | F25: 47528 | G25: 97.3 | I25: 100.312 | J25: 102.125 | K25: =IF(AF25="","",AF25/Z25) -> 0.094247246 | L25: 8.9617325 | M25: 2.5650448 | O25: B2 | Q25: Líneas Aéreas | R25: GB | S25: USD | T25: NORMAL | V25: Secured | W25: =+D25*G25/100 -> 1430.8824 | X25: =+D25*G25/100 -> 1430.8824 | Z25: =+D25*J25/100 -> 1501.8382 | AA25: =IF(+I25=0,AB25,D25*(J25-I25)/100) -> 26.661765 | AB25: =+$D25*($J25-$G25)/100 -> 70.955882 | AC25: =+Z25*L25 -> 13459.073 | AD25: =+Z25*M25 -> 3852.2823 | AE25: =+AA25/X25 -> 0.018633094 | AF25: =+D25*E25/100 -> 141.54412 | AG25: 45904 | AJ25: 0.4 | AK25: =AJ25*Z25 -> 600.73529
D27: =SUM(D4:D26) -> 68644.118 | Z27: =SUM(Z4:Z26) -> 67826.196 | AA27: =SUM(AA4:AA26) -> 208.16608 | AB27: =SUM(AB4:AB26) -> 77.057354 | AC27: =SUM(AC4:AC26) -> 294119.05 | AD27: =SUM(AD4:AD26) -> 91320.784 | AF27: =SUM(AF4:AF26) -> 2955.5509
AF28: =AF27/360*AE31 -> 845.61595
AB29: IRR | AC29: =AC27/Z27 -> 4.3363637 | AE29: =TODAY() -> 46125
AB30: Dur | AC30: =AD27/Z27 -> 1.346394 | AE30: 46022
AE31: =AE29-AE30 -> 103
A33: RENTA FIJA (BANCO MALO)
A34: BANCO | B34: ISIN | C34: Name | D34: Monto Compra | E34: Coupon | F34: Maturity | G34: PRECIO COMPRA | H34: Precio 31-Dic-2021 | I34: Precio 31-Dic-2024 | J34: Precio Mercado (29-05) | K34: CurrYield | L34: YLD_YTM_ask | M34: DUR_MID | N34: rtg_sp | O34: rtg_moody | P34: rtg_fitch | Q34: industry_subgroup | R34: PAIS | S34: crncy | T34: callable | U34: NXT_CALL_DT | V34: payment_rank | W34: Monto Compra | X34: Costo | Y34: status | Z34: VP | AA34: MTM | AB34: MTM trib | AC34: VPxYTM | AD34: VPxDur | AE34: Rt % año | AF34: INTERESES x AÑO | AG34: FECHA COMPRA | AH34: VENTA | AI34: compra | AJ34: LTV
A35: SCH | B35: XS145DGFDJHDKJ | C35: bono22 | D35: 294.11765 | E35: 12.75 | F35: 17-02-2022 | G35: 61.45537 | H35: 5.246 | I35: 13.16 | J35: 41.35 | K35: =IF(AF35="","",AF35/Z35) | L35: 72.944676 | M35: 0 | N35: #N/A N/A | O35: #N/A N/A | P35: WD | Q35: Oil Comp-Integrated | R35: VE | S35: USD | T35: SINKABLE | V35: Sr Unsecured | W35: =+D35*J35/100 -> 121.61765 | X35: =+D35*G35/100 -> 180.75109 | Z35: =+D35*J35/100 -> 121.61765 | AA35: =IF(+I35=0,AB35,W35*(J35-I35)/100) -> 34.284015 | AB35: =+$W35*($J35-$G35)/100 -> -24.451678 | AC35: =+Z35*L35 -> 8871.3599 | AE35: =+AA35/X35 -> 0.18967529 | AJ35: 0 | AK35: =AJ35*Z35 -> 0
A36: SCH | B36: XS145DGFDJHDKJ | C36: bono23 | D36: 294.11765 | E36: 8.25 | F36: 20-01-2016 | G36: 85.405 | H36: 0.404 | I36: 0.221 | J36: 0.113 | K36: =IF(AF36="","",AF36/Z36) | L36: 4166.6667 | M36: 0 | N36: NR | O36: WR | P36: #N/A N/A | Q36: Commer Banks Non-US | R36: BR | S36: USD | T36: AT MATURITY | V36: Sr Unsecured | W36: =+D36*G36/100 -> 251.19118 | X36: =+D36*G36/100 -> 251.19118 | Z36: =+D36*J36/100 -> 0.33235294 | AA36: =IF(+I36=0,AB36,W36*(J36-I36)/100) -> -0.27128647 | AB36: =+$W36*($J36-$G36)/100 -> -214.24598 | AC36: =+Z36*L36 -> 1384.8039 | AD36: =+Z36*M36 -> 0 | AE36: =+AA36/X36 -> -0.00108 | AK36: =AJ36*Z36 -> 0
A37: SCH | B37: XS145DGFDJHDKJ | C37: bono24 | D37: 588.23529 | E37: 5.25 | F37: 23-05-2023 | G37: 93.5 | H37: 14.102 | I37: 33.854 | J37: 6.875 | K37: =IF(AF37="","",AF37/Z37) | L37: 59.456399 | M37: 0 | N37: #N/A N/A | O37: #N/A N/A | P37: WD | Q37: Commer Banks Non-US | R37: RU | S37: USD | T37: AT MATURITY | V37: Subordinated | W37: =+D37*G37/100 -> 550 | X37: =+D37*G37/100 -> 550 | Z37: =+D37*J37/100 -> 40.441176 | AA37: =IF(+I37=0,AB37,W37*(J37-I37)/100) -> -148.3845 | AB37: =+$W37*($J37-$G37)/100 -> -476.4375 | AC37: =+Z37*L37 -> 2404.4867 | AD37: =+Z37*M37 -> 0 | AE37: =+AA37/X37 -> -0.26979 | AJ37: 0 | AK37: =AJ37*Z37 -> 0
A38: SCH | B38: XS145DGFDJHDKJ | C38: bono25 | D38: 735.29412 | E38: 6.75 | F38: 15-03-2023 | G38: 95.55862 | H38: 5.558 | I38: 3.488 | J38: 3 | K38: =IF(AF38="","",AF38/Z38) | L38: 162.6506 | M38: 0 | N38: NR | O38: WR | P38: #N/A N/A | Q38: Commer Banks Non-US | R38: CL | S38: USD | T38: CALLABLE | V38: Sr Unsecured | W38: =+D38*G38/100 -> 702.63691 | X38: =+D38*G38/100 -> 702.63691 | Z38: =+D38*J38/100 -> 22.058824 | AA38: =IF(+I38=0,AB38,W38*(J38-I38)/100) -> -3.4288681 | AB38: =+$W38*($J38-$G38)/100 -> -650.35103 | AC38: =+Z38*L38 -> 3587.8809 | AD38: =+Z38*M38 -> 0 | AE38: =+AA38/X38 -> -0.00488 | AJ38: 0 | AK38: =AJ38*Z38 -> 0
A39: SCH | B39: XS145DGFDJHDKJ | C39: bono26 | D39: 735.29412 | E39: 6.75 | F39: 15-03-2023 | G39: 96.15 | H39: 5.558 | I39: 3.488 | J39: 3 | K39: =IF(AF39="","",AF39/Z39) | L39: 162.6506 | M39: 0 | N39: NR | O39: WR | P39: #N/A N/A | Q39: Commer Banks Non-US | R39: CL | S39: USD | T39: CALLABLE | V39: Sr Unsecured | W39: =+D39*G39/100 -> 706.98529 | X39: =+D39*G39/100 -> 706.98529 | Z39: =+D39*J39/100 -> 22.058824 | AA39: =IF(+I39=0,AB39,W39*(J39-I39)/100) -> -3.4500882 | AB39: =+$W39*($J39-$G39)/100 -> -658.5568 | AC39: =+Z39*L39 -> 3587.8809 | AD39: =+Z39*M39 -> 0 | AE39: =+AA39/X39 -> -0.00488 | AJ39: 0 | AK39: =AJ39*Z39 -> 0
A40: SCH | B40: XS145DGFDJHDKJ | C40: bono27 | D40: 441.17647 | E40: 12 | F40: 04-05-2013 | G40: 0 | H40: 0.378 | I40: 0.378 | J40: 0.216 | K40: =IF(AF40="","",AF40/Z40) | L40: 3174.6032 | M40: 0 | N40: #N/A N/A | O40: WR | P40: #N/A N/A | Q40: Steel Pipe&Tube | R40: BG | S40: EUR | T40: AT MATURITY | V40: Secured | W40: =+D40*G40/100 -> 0 | X40: =+D40*G40/100 -> 0 | Z40: =+D40*J40/100 -> 0.95294118 | AA40: =IF(+I40=0,AB40,W40*(J40-I40)/100) -> 0 | AB40: =+$W40*($J40-$G40)/100 -> 0 | AC40: =+Z40*L40 -> 3025.2101 | AD40: =+Z40*M40 -> 0 | AE40: =+AA40/X40 -> #DIV/0! | AK40: =AJ40*Z40 -> 0
A41: SCH | B41: XS145DGFDJHDKJ | C41: bono28 | D41: 1470.5882 | E41: 7.121 | F41: 25-06-2024 | G41: 104 | H41: 23.415 | I41: 23.722 | J41: 15.809 | K41: =IF(AF41="","",AF41/Z41) | L41: 38.326157 | M41: 0 | N41: NR | O41: #N/A N/A | P41: WD | Q41: Commer Banks Non-US | R41: RU | S41: USD | T41: AT MATURITY | V41: Sr Unsecured | W41: =+D41*G41/100 -> 1529.4118 | X41: =+D41*G41/100 -> 1529.4118 | Z41: =+D41*J41/100 -> 232.48529 | AA41: =IF(+I41=0,AB41,W41*(J41-I41)/100) -> -121.02235 | AB41: =+$W41*($J41-$G41)/100 -> -1348.8035 | AC41: =+Z41*L41 -> 8910.2679 | AD41: =+Z41*M41 -> 0 | AE41: =+AA41/X41 -> -0.07913 | AJ41: 0 | AK41: =AJ41*Z41 -> 0
A42: SCH | B42: XS145DGFDJHDKJ | C42: bono29 | D42: 294.11765 | E42: 9.75 | F42: 17-05-2035 | G42: 48.99444 | H42: 4.82 | I42: 12.671 | J42: 39.05 | K42: =IF(AF42="","",AF42/Z42) | L42: 52.656709 | M42: 2.9279895 | N42: #N/A N/A | O42: WR | P42: WD | Q42: Oil Comp-Integrated | R42: VE | S42: USD | T42: SINKABLE | V42: Sr Unsecured | W42: =+D42*G42/100 -> 144.10129 | X42: =+D42*G42/100 -> 144.10129 | Z42: =+D42*J42/100 -> 114.85294 | AA42: =IF(+I42=0,AB42,W42*(J42-I42)/100) -> 38.01248 | AB42: =+$W42*($J42-$G42)/100 -> -14.330067 | AJ42: 0 | AK42: =AJ42*Z42 -> 0
A43: SCH | B43: XS145DGFDJHDKJ | C43: bono30 | D43: 2941.1765 | E43: 4.7 | F43: 29-01-2025 | G43: 98.88 | H43: 22.724 | I43: 35.583 | J43: #N/A N/A | K43: =IF(AF43="","",AF43/Z43) | L43: 0 | M43: 0 | N43: NR | O43: #N/A N/A | P43: WD | Q43: Commer Banks Non-US | R43: RU | S43: USD | T43: AT MATURITY | V43: Sr Unsecured | W43: =+D43*G43/100 -> 2908.2353 | X43: =+D43*G43/100 -> 2908.2353 | Z43: 0 | AA43: 0 | AB43: 0 | AC43: =+Z43*L43 -> 0 | AD43: =+Z43*M43 -> 0 | AE43: =+AA43/X43 -> 0 | AJ43: 0 | AK43: =AJ43*Z43 -> 0
...

Sheet Equity
C4: =+cartera!V92 -> AMZN | D4: =+cartera!W92 -> ARGT | E4: =+cartera!X92 -> BCH | F4: =+cartera!Y92 -> BLK | G4: =+cartera!Z92 -> BRK/B | H4: =+cartera!AA92 -> CRCL | I4: =+cartera!AB92 -> AIQ | J4: =+cartera!AC92 -> QQQ | ... AG4: =+cartera!AZ92 -> TCEHY
C5: =+cartera!V151 -> 2995.8912 | D5: =+cartera!W151 -> -697.4376 | E5: =+cartera!X151 -> -689.22 | F5: =+cartera!Y151 -> -28073.78 | G5: =+cartera!Z151 -> -18241.52 | H5: =+cartera!AA151 -> -5701.0608 | I5: =+cartera!AB151 -> -10125.54 | J5: =+cartera!AC151 -> -251787.62 | ... AG5: =+cartera!AZ151 -> -32696.16
M8: TICKER | N8: VP USD | O8: % | P8: Rt 2026
M9: AMZN | N9: =_xlfn.XLOOKUP(M9,C$4:AG$4,C$5:AG$5,"") -> 2995.8912 | O9: =+N9/N$42 -> -6.5078894e-05
M10: ARGT | N10: =_xlfn.XLOOKUP(M10,C$4:AG$4,C$5:AG$5,"") -> -697.4376 | O10: =+N10/N$42 -> 1.5150239e-05
M11: BCH | N11: =_xlfn.XLOOKUP(M11,C$4:AG$4,C$5:AG$5,"") -> -689.22 | O11: =+N11/N$42 -> 1.497173e-05
M12: BLK | N12: =_xlfn.XLOOKUP(M12,C$4:AG$4,C$5:AG$5,"") -> -28073.78 | O12: =+N12/N$42 -> 0.00060983876
M13: BRK/B | N13: =_xlfn.XLOOKUP(M13,C$4:AG$4,C$5:AG$5,"") -> -18241.52 | O13: =+N13/N$42 -> 0.00039625536
M14: CRCL | N14: =_xlfn.XLOOKUP(M14,C$4:AG$4,C$5:AG$5,"") -> -5701.0608 | O14: =+N14/N$42 -> 0.00012384253
M15: AIQ | N15: =_xlfn.XLOOKUP(M15,C$4:AG$4,C$5:AG$5,"") -> -10125.54 | O15: =+N15/N$42 -> 0.00021995423
M16: QQQ | N16: =_xlfn.XLOOKUP(M16,C$4:AG$4,C$5:AG$5,"") -> -251787.62 | O16: =+N16/N$42 -> 0.005469511
M17: ESM6 | N17: =_xlfn.XLOOKUP(M17,C$4:AG$4,C$5:AG$5,"") -> -43971928 | O17: =+N17/N$42 -> 0.95518971
M18: SPY | N18: =_xlfn.XLOOKUP(M18,C$4:AG$4,C$5:AG$5,"") -> -194265.5 | O18: =+N18/N$42 -> 0.0042199743
M19: GOOG | N19: =_xlfn.XLOOKUP(M19,C$4:AG$4,C$5:AG$5,"") -> -49953.28 | O19: =+N19/N$42 -> 0.0010851209
M20: LTM | N20: =_xlfn.XLOOKUP(M20,C$4:AG$4,C$5:AG$5,"") -> -48814.2 | O20: =+N20/N$42 -> 0.001060377
... M39: TCEHY | N39: =_xlfn.XLOOKUP(M39,C$4:AG$4,C$5:AG$5,"") -> -32696.16 | O39: =+N39/N$42 -> 0.0007102494
M42: TOTAL | N42: =SUM(N9:N41) -> -46034759

Sheet registro
